Workbook

Sheet Resumen Presupuestal
A1: PROYECTO FARMALINK - PRESUPUESTO GENERAL CORPORATIVO
A3: N° | B3: Rubro / Categoría Presupuestal | C3: Subtotal Estimado (COP) | D3: % Participación | E3: Alcance y Descripción Estratégica
A4: 1 | B4: 1. Talento Humano y Consultoría de Ingeniería de Software | C4: ='Detalle de Costos'!C17 -> 296450000 | D4: ='Detalle de Costos'!C17/$C$11 -> 0.71311389 | E4: Equipo de desarrollo senior, arquitectura, gestión PMO, QA y DBA (3.5 meses / 14 semanas)
A5: 2 | B5: 2. Infraestructura Cloud Empresarial y Alta Disponibilidad | C5: ='Detalle de Costos'!C26 -> 25175000 | D5: ='Detalle de Costos'!C26/$C$11 -> 0.060558752 | E5: Cluster Kubernetes, Multi-AZ DB PostgreSQL con Réplica, Redis Cache, AWS WAF, S3 y CDN
A6: 3 | B6: 3. Licenciamiento, APIs de Servicios y Herramientas DevOps | C6: ='Detalle de Costos'!C35 -> 17195000 | D6: ='Detalle de Costos'!C35/$C$11 -> 0.04136277 | E6: Google Maps Enterprise Plan (Directions/Places), CI/CD GitHub Enterprise, Datadog y Figma Org
A7: 4 | B7: 4. Auditoría de Seguridad, Cumplimiento y Pruebas Especializadas | C7: ='Detalle de Costos'!C42 -> 18800000 | D7: ='Detalle de Costos'!C42/$C$11 -> 0.045223616 | E7: Pentesting de caja negra/blanca, análisis estático SonarQube, pruebas de carga (JMeter) y Habeas Data
A8: 5 | B8: 5. Operaciones de Campo, Georreferenciación y Despliegue Piloto | C8: ='Detalle de Costos'!C49 -> 13700000 | D8: ='Detalle de Costos'!C49/$C$11 -> 0.032955508 | E8: Levantamiento presencial de 100+ farmacias, digitalización de inventarios, pruebas en campo y UX Lab
A9: 6 | B9: 6. Gestión Jurídica, Propiedad Intelectual y Asesoría Legal | C9: ='Detalle de Costos'!C54 -> 6600000 | D9: ='Detalle de Costos'!C54/$C$11 -> 0.015876376 | E9: Registro de software en DNDA, términos y condiciones de pasarela de compra, contratos de datos
A10: 7 | B10: 7. Reserva de Contingencia y Gestión de Riesgos (10%) | C10: ='Detalle de Costos'!C58 -> 37792000 | D10: ='Detalle de Costos'!C58/$C$11 -> 0.090909091 | E10: Fondo para amortiguar fluctuaciones de consumo de APIs, escalabilidad e imprevistos técnicos
A11: PRESUPUESTO TOTAL ESTIMADO DEL PROYECTO | C11: =SUM(C4:C10) -> 415712000 | D11: =SUM(D4:D10) -> 1 | E11: Inversión para ciclo de vida 14 semanas

Sheet Detalle de Costos
A1: DESGLOSE DETALLADO DE COSTOS Y HONORARIOS PROFESIONALES - FARMALINK
A3: Ítem / Concepto | B3: Unidad | C3: Costo Total (COP) | D3: Cantidad / Meses | E3: Tarifa Mensual / Unitaria (COP) | F3: Responsable / Rol | G3: Observaciones y Especificación Técnica
A4: 1. TALENTO HUMANO Y CONSULTORÍA DE INGENIERÍA DE SOFTWARE (14 SEMANAS / 3.5 MESES)
A5: Director de Proyecto / Project Manager (PMP/Scrum Master) | B5: Mes | C5: =D5*E5 -> 33250000 | D5: 3.5 | E5: 9500000 | F5: Sergio Andrés Merchán Rozo | G5: Gestión integral del proyecto, gobierno Scrum, control de hitos, riesgos y entregas
A6: Arquitecto de Software Senior | B6: Mes | C6: =D6*E6 -> 30800000 | D6: 3.5 | E6: 8800000 | F6: Juan David Cardozo Prada | G6: Diseño de microservicios/monolito modular, patrones de concurrencia y escalabilidad
A7: Especialista Cloud & DevOps Engineer | B7: Mes | C7: =D7*E7 -> 27300000 | D7: 3.5 | E7: 7800000 | F7: Juan David Cardozo Prada | G7: Infraestructura como código (Terraform), pipelines CI/CD, clusters Docker/K8s y monitoreo
A8: Líder de Base de Datos y DBA | B8: Mes | C8: =D8*E8 -> 26250000 | D8: 3.5 | E8: 7500000 | F8: Julián Santiago Ayala Méndez | G8: Modelado relacional PostgreSQL, indexación geoespacial PostGIS, particionamiento e integridad
A9: Analista de Negocio y Requisitos de Software | B9: Mes | C9: =D9*E9 -> 23800000 | D9: 3.5 | E9: 6800000 | F9: Julián Santiago Ayala Méndez | G9: Levantamiento de especificaciones SRS, modelado de procesos BPMN y validación de reglas de negocio
A10: Desarrollador Backend Senior (Core & APIs) | B10: Mes | C10: =D10*E10 -> 28000000 | D10: 3.5 | E10: 8000000 | F10: José Santiago Soler Siza | G10: Desarrollo de API RESTful, motor de búsqueda, comparador de precios y transacciones de compra
A11: Desarrollador Backend Semi-Senior (Integraciones) | B11: Mes | C11: =D11*E11 -> 21000000 | D11: 3.5 | E11: 6000000 | F11: Equipo Backend FarmaLink | G11: Integración con API de georreferenciación, pasarela de pago y servicios externos
A12: Líder de Desarrollo Frontend Senior | B12: Mes | C12: =D12*E12 -> 26250000 | D12: 3.5 | E12: 7500000 | F12: Haiver Darío Daza Cerdas | G12: Arquitectura frontend (React/Next.js), consumo de APIs, estado global y rendimiento web
A13: Diseñador UI/UX y Product Designer | B13: Mes | C13: =D13*E13 -> 22750000 | D13: 3.5 | E13: 6500000 | F13: Haiver Darío Daza Cerdas | G13: Design system, prototipado interactivo de alta fidelidad, usabilidad y pruebas heurísticas
A14: Ingeniero de Calidad y Pruebas QA Lead | B14: Mes | C14: =D14*E14 -> 23800000 | D14: 3.5 | E14: 6800000 | F14: Gabriel Mateo Contreras Toquica | G14: Automatización de pruebas E2E (Cypress/Selenium), pruebas de integración y matrices de prueba
A15: Ingeniero QA Junior / Tester Funcional | B15: Mes | C15: =D15*E15 -> 15750000 | D15: 3.5 | E15: 4500000 | F15: Gabriel Mateo Contreras Toquica | G15: Ejecución de pruebas manuales, cross-browser, responsive design y reporte de defectos
A16: Documentador y Redactor Técnico Senior | B16: Mes | C16: =D16*E16 -> 17500000 | D16: 3.5 | E16: 5000000 | F16: Diego Alexander López Arévalo | G16: Manuales técnicos, guías de usuario final, documentación de APIs Swagger y actas PMBOK
A17: SUBTOTAL TALENTO HUMANO Y CONSULTORÍA | C17: =SUM(C5:C16) -> 296450000
A18: 2. INFRAESTRUCTURA CLOUD EMPRESARIAL Y ALTA DISPONIBILIDAD
A19: Cluster de Cómputo Cloud (Kubernetes / Multi-Instancias) | B19: Mes | C19: =D19*E19 -> 7400000 | D19: 4 | E19: 1850000 | F19: Juan David Cardozo | G19: Cluster cloud redundante de alta disponibilidad (8 vCPU, 32GB RAM, auto-escalado)
A20: Servicio Cloud de Base de Datos PostgreSQL Multi-AZ | B20: Mes | C20: =D20*E20 -> 6400000 | D20: 4 | E20: 1600000 | F20: Julián Santiago Ayala | G20: Instancia gestionada con réplica de lectura, soporte PostGIS, backups diarios y failover
A21: Servidor de Cache en Memoria (Redis Enterprise) | B21: Mes | C21: =D21*E21 -> 2600000 | D21: 4 | E21: 650000 | F21: Santiago Soler | G21: Caché de alta velocidad para optimizar consultas frecuentes de precios y farmacias
A22: Almacenamiento de Objetos S3 / Blob Storage & CDN | B22: Mes | C22: =D22*E22 -> 1800000 | D22: 4 | E22: 450000 | F22: Juan David Cardozo | G22: Distribución global de assets (fotos de fármacos) mediante CloudFront CDN
A23: Firewall de Aplicaciones Web (AWS WAF) & Protección DDoS | B23: Mes | C23: =D23*E23 -> 3400000 | D23: 4 | E23: 850000 | F23: Juan David Cardozo | G23: Reglas OWASP Top 10, rate limiting y protección contra ataques automatizados
A24: Certificados SSL / TLS Empresariales EV & Dominio | B24: Global | C24: =D24*E24 -> 950000 | D24: 1 | E24: 950000 | F24: Sergio Merchán | G24: Certificado de Validación Extendida para transacciones seguras y dominios corporativos
A25: Ambientes Redundantes de Staging / Testing y Sandbox | B25: Mes | C25: =D25*E25 -> 2625000 | D25: 3.5 | E25: 750000 | F25: Juan David Cardozo | G25: Infraestructura aislada para homologación y pruebas de QA
A26: SUBTOTAL INFRAESTRUCTURA CLOUD | C26: =SUM(C19:C25) -> 25175000
A27: 3. LICENCIAMIENTO, APIS DE SERVICIOS Y HERRAMIENTAS DEVOPS
A28: Google Maps Platform API Enterprise (Directions/Places/Geocoding) | B28: Mes | C28: =D28*E28 -> 5775000 | D28: 3.5 | E28: 1650000 | F28: Santiago Soler / Juan Cardozo | G28: Paquete para alto volumen de geocodificación, render de mapas y cálculo de rutas óptimas
A29: Plataforma de Observabilidad y Monitoreo APM (Datadog / Sentry) | B29: Mes | C29: =D29*E29 -> 2975000 | D29: 3.5 | E29: 850000 | F29: Juan David Cardozo | G29: Monitoreo en tiempo real de endpoints, rastreo de trazas distribuidas y alertas
A30: Suite de Gestión Ágil y Documentación (Jira / Confluence Enterprise) | B30: Mes | C30: =D30*E30 -> 2170000 | D30: 3.5 | E30: 620000 | F30: Sergio Andrés Merchán | G30: Control de épicas, historias de usuario, sprints, tableros Kanban y artefactos
A31: Plataforma de Diseño Colaborativo Figma Organization | B31: Mes | C31: =D31*E31 -> 1680000 | D31: 3.5 | E31: 480000 | F31: Haiver Darío Daza | G31: Gestión de librerías de componentes UI, design tokens y prototipos interactivos
A32: GitHub Enterprise Cloud & Runners Dedicados de CI/CD | B32: Mes | C32: =D32*E32 -> 1925000 | D32: 3.5 | E32: 550000 | F32: Juan David Cardozo | G32: Repositorio corporativo con análisis de código, escaneo de dependencias y pipelines
A33: Servicios Transaccionales de Notificaciones (Twilio / SendGrid) | B33: Mes | C33: =D33*E33 -> 1820000 | D33: 3.5 | E33: 520000 | F33: Santiago Soler | G33: Envío de códigos OTP de seguridad, confirmaciones de compra y alertas de cambio de precios
A34: Licenciamiento de Herramientas de Modelado de BD y Arquitectura | B34: Global | C34: =D34*E34 -> 850000 | D34: 1 | E34: 850000 | F34: Julián Ayala / Juan Cardozo | G34: Software profesional para diseño DER (DataGrip/Enterprise Architect)
A35: SUBTOTAL LICENCIAS, APIS Y HERRAMIENTAS | C35: =SUM(C28:C34) -> 17195000
A36: 4. AUDITORÍA DE SEGURIDAD, CUMPLIMIENTO Y PRUEBAS ESPECIALIZADAS
A37: Auditoría de Ciberseguridad Externa y Ethical Hacking (Pentesting) | B37: Global | C37: =D37*E37 -> 6500000 | D37: 1 | E37: 6500000 | F37: Gabriel Contreras / Consultor Externo | G37: Pruebas de penetración sobre APIs, inyecciones SQL, autenticación y sesión
A38: Análisis Estático de Código Fuente y Vulnerabilidades (SAST/DAST) | B38: Global | C38: =D38*E38 -> 2800000 | D38: 1 | E38: 2800000 | F38: Gabriel Mateo Contreras | G38: Escaneo automatizado con SonarQube Enterprise para deuda técnica y seguridad
A39: Pruebas de Estrés, Concurrencia y Rendimiento (Load Testing) | B39: Global | C39: =D39*E39 -> 3200000 | D39: 1 | E39: 3200000 | F39: Gabriel Contreras / Juan Cardozo | G39: Simulación de 10.000 usuarios concurrentes mediante JMeter/k6 y pruebas de cuello de botella
A40: Auditoría y Certificación de Cumplimiento de Datos (Habeas Data) | B40: Global | C40: =D40*E40 -> 3800000 | D40: 1 | E40: 3800000 | F40: Julián Ayala / Diego López | G40: Verificación del cumplimiento de la Ley 1581 de 2012 para manejo de datos de usuarios
A41: Laboratorio de Pruebas de Usabilidad con Usuarios Reales | B41: Global | C41: =D41*E41 -> 2500000 | D41: 1 | E41: 2500000 | F41: Haiver Daza / Gabriel Contreras | G41: Sesiones grabadas con usuarios finales para evaluar curva de aprendizaje y accesibilidad
...

Sheet Flujo de Caja por Sprints
A1: PROYECCIÓN DE FLUJO DE CAJA Y DISTRIBUCIÓN POR SPRINT
A3: Rubro Presupuestal | B3: Sprint 0 (12-19 Ago) | C3: Sprint 1 (19 Ago-02 Sep) | D3: Sprint 2 (02-16 Sep) | E3: Sprint 3 (16-30 Sep) | F3: Sprint 4 (30 Sep-14 Oct) | G3: Sprint 5 (14-28 Oct) | H3: Sprint 6 (28 Oct-11 Nov) | I3: Sprint 7 (11-18 Nov) | J3: Total Rubro
A4: 1. Talento Humano | B4: ='Detalle de Costos'!C17*(1/14) -> 21175000 | C4: ='Detalle de Costos'!C17*(2/14) -> 42350000 | D4: ='Detalle de Costos'!C17*(2/14) -> 42350000 | E4: ='Detalle de Costos'!C17*(2/14) -> 42350000 | F4: ='Detalle de Costos'!C17*(2/14) -> 42350000 | G4: ='Detalle de Costos'!C17*(2/14) -> 42350000 | H4: ='Detalle de Costos'!C17*(2/14) -> 42350000 | I4: ='Detalle de Costos'!C17*(1/14) -> 21175000 | J4: =SUM(B4:I4) -> 296450000
A5: 2. Infraestructura Cloud | B5: ='Detalle de Costos'!C26*(1/14) -> 1798214.3 | C5: ='Detalle de Costos'!C26*(2/14) -> 3596428.6 | D5: ='Detalle de Costos'!C26*(2/14) -> 3596428.6 | E5: ='Detalle de Costos'!C26*(2/14) -> 3596428.6 | F5: ='Detalle de Costos'!C26*(2/14) -> 3596428.6 | G5: ='Detalle de Costos'!C26*(2/14) -> 3596428.6 | H5: ='Detalle de Costos'!C26*(2/14) -> 3596428.6 | I5: ='Detalle de Costos'!C26*(1/14) -> 1798214.3 | J5: =SUM(B5:I5) -> 25175000
A6: 3. Licenciamiento y APIs | B6: ='Detalle de Costos'!C35*0.05 -> 859750 | C6: ='Detalle de Costos'!C35*0.15 -> 2579250 | D6: ='Detalle de Costos'!C35*0.15 -> 2579250 | E6: ='Detalle de Costos'!C35*0.15 -> 2579250 | F6: ='Detalle de Costos'!C35*0.2 -> 3439000 | G6: ='Detalle de Costos'!C35*0.15 -> 2579250 | H6: ='Detalle de Costos'!C35*0.1 -> 1719500 | I6: ='Detalle de Costos'!C35*0.05 -> 859750 | J6: =SUM(B6:I6) -> 17195000
A7: 4. Seguridad y Auditorías | B7: ='Detalle de Costos'!C42*0 -> 0 | C7: ='Detalle de Costos'!C42*0.1 -> 1880000 | D7: ='Detalle de Costos'!C42*0.1 -> 1880000 | E7: ='Detalle de Costos'!C42*0.15 -> 2820000 | F7: ='Detalle de Costos'!C42*0.15 -> 2820000 | G7: ='Detalle de Costos'!C42*0.2 -> 3760000 | H7: ='Detalle de Costos'!C42*0.25 -> 4700000 | I7: ='Detalle de Costos'!C42*0.05 -> 940000 | J7: =SUM(B7:I7) -> 18800000
A8: 5. Operaciones y Campo | B8: ='Detalle de Costos'!C49*0.05 -> 685000 | C8: ='Detalle de Costos'!C49*0.05 -> 685000 | D8: ='Detalle de Costos'!C49*0.1 -> 1370000 | E8: ='Detalle de Costos'!C49*0.15 -> 2055000 | F8: ='Detalle de Costos'!C49*0.25 -> 3425000 | G8: ='Detalle de Costos'!C49*0.25 -> 3425000 | H8: ='Detalle de Costos'!C49*0.1 -> 1370000 | I8: ='Detalle de Costos'!C49*0.05 -> 685000 | J8: =SUM(B8:I8) -> 13700000
A9: 6. Gestión Jurídica / Legal | B9: ='Detalle de Costos'!C54*0.2 -> 1320000 | C9: ='Detalle de Costos'!C54*0.2 -> 1320000 | D9: ='Detalle de Costos'!C54*0.1 -> 660000 | E9: ='Detalle de Costos'!C54*0.1 -> 660000 | F9: ='Detalle de Costos'!C54*0.1 -> 660000 | G9: ='Detalle de Costos'!C54*0.1 -> 660000 | H9: ='Detalle de Costos'!C54*0.1 -> 660000 | I9: ='Detalle de Costos'!C54*0.1 -> 660000 | J9: =SUM(B9:I9) -> 6600000
A10: 7. Reserva Contingencia | B10: ='Detalle de Costos'!C58*0 -> 0 | C10: ='Detalle de Costos'!C58*0.1 -> 3779200 | D10: ='Detalle de Costos'!C58*0.15 -> 5668800 | E10: ='Detalle de Costos'!C58*0.15 -> 5668800 | F10: ='Detalle de Costos'!C58*0.2 -> 7558400 | G10: ='Detalle de Costos'!C58*0.2 -> 7558400 | H10: ='Detalle de Costos'!C58*0.15 -> 5668800 | I10: ='Detalle de Costos'!C58*0.05 -> 1889600 | J10: =SUM(B10:I10) -> 37792000
A11: DESEMBOLSO POR SPRINT | B11: =SUM(B4:B10) -> 25837964 | C11: =SUM(C4:C10) -> 56189879 | D11: =SUM(D4:D10) -> 58104479 | E11: =SUM(E4:E10) -> 59729479 | F11: =SUM(F4:F10) -> 63848829 | G11: =SUM(G4:G10) -> 63929079 | H11: =SUM(H4:H10) -> 60064729 | I11: =SUM(I4:I10) -> 28007564 | J11: =SUM(J4:J10) -> 415712000
A12: COSTO ACUMULADO | B12: =B11 -> 25837964 | C12: =B12+C11 -> 82027843 | D12: =C12+D11 -> 1.4013232e+08 | E12: =D12+E11 -> 199861800 | F12: =E12+F11 -> 2.6371063e+08 | G12: =F12+G11 -> 3.2763971e+08 | H12: =G12+H11 -> 3.8770444e+08 | I12: =H12+I11 -> 415712000 | J12: =I12 -> 415712000
